<?xml version="1.0" encoding="utf-8"?>
<!-- This URDF was automatically created by SolidWorks to URDF Exporter! Originally created by Stephen Brawner (brawner@gmail.com) 
     Commit Version: 1.5.1-0-g916b5db  Build Version: 1.5.7152.31018
     For more information, please see http://wiki.ros.org/sw_urdf_exporter -->
<robot
  name="vss_robot">

  <link
    name="corpo">

    <inertial>
      <origin
        xyz="0.040614 0.02701 0.019376"
        rpy="0 0 0" />
      <mass
        value="0.11426" />
      <inertia
        ixx="5.051E-05"
        ixy="-5.9966E-09"
        ixz="-4.914E-06"
        iyy="5.6433E-05"
        iyz="4.347E-13"
        izz="8.1071E-05" />
    </inertial>

    <visual>
      <origin
        xyz="0 0 0"
        rpy="0 0 0" />
      <geometry>
        <mesh
          filename="package://vss_simulation/meshes/corpo.STL" />
      </geometry>
      <material
        name="">
        <color
          rgba="1 1 1 1" />
      </material>
    </visual>

    <collision>
      <origin
        xyz="0 0 0"
        rpy="0 0 0" />
      <geometry>
        <mesh
          filename="package://vss_simulation/meshes/corpo.STL" />
      </geometry>
    </collision>

  </link>


  <link
    name="roda_esq_link">

    <inertial>
      <origin
        xyz="-1.3546E-07 -3.5231E-06 -0.0037178"
        rpy="0 0 0" />
      <mass
        value="0.017155" />
      <inertia
        ixx="4.35E-06"
        ixy="-1.602E-15"
        ixz="-8.2955E-17"
        iyy="4.3503E-06"
        iyz="-6.2762E-17"
        izz="8.5226E-06" />
    </inertial>

    <visual>
      <origin
        xyz="0 0 0"
        rpy="0 0 0" />
      <geometry>
        <mesh
          filename="package://vss_simulation/meshes/roda_esq_link.STL" />
      </geometry>
      <material
        name="">
        <color
          rgba="0.69804 0.69804 0.69804 1" />
      </material>
    </visual>

    <collision>
      <origin
        xyz="0 0 0"
        rpy="0 0 0" />
      <geometry>
        <mesh
          filename="package://vss_simulation/meshes/roda_esq_link.STL" />
      </geometry>
    </collision>

  </link>


  <joint
    name="roda_esq_joint"
    type="continuous">
    <origin
      xyz="0.032248 0.0632 0.026799"
      rpy="1.5708 -0.013398 3.1416" />
    <parent
      link="corpo" />
    <child
      link="roda_esq_link" />
    <axis
      xyz="0 0 1" />
  </joint>


  <link
    name="roda_dir_link">

    <inertial>
      <origin
        xyz="-4.52E-08 -3.5231E-06 -0.0037178"
        rpy="0 0 0" />
      <mass
        value="0.017155" />
      <inertia
        ixx="4.35E-06"
        ixy="1.602E-15"
        ixz="-8.2955E-17"
        iyy="4.3503E-06"
        iyz="6.2765E-17"
        izz="8.5226E-06" />
    </inertial>

    <visual>
      <origin
        xyz="0 0 0"
        rpy="0 0 0" />
      <geometry>
        <mesh
          filename="package://vss_simulation/meshes/roda_dir_link.STL" />
      </geometry>
      <material
        name="">
        <color
          rgba="0.69804 0.69804 0.69804 1" />
      </material>
    </visual>

    <collision>
      <origin
        xyz="0 0 0"
        rpy="0 0 0" />
      <geometry>
        <mesh
          filename="package://vss_simulation/meshes/roda_dir_link.STL" />
      </geometry>
    </collision>

  </link>


  <joint
    name="roda_dir_joint"
    type="continuous">
    <origin
      xyz="0.032251 -0.0092 0.026799"
      rpy="1.5708 -0.2572 0" />
    <parent
      link="corpo" />
    <child
      link="roda_dir_link" />
    <axis
      xyz="0 0 -1" />
  </joint>


  <link
    name="chapeu_link">

    <inertial>
      <origin
        xyz="0.037495 0.0375 -0.0019927"
        rpy="0 0 0" />
      <mass
        value="0.022727" />
      <inertia
        ixx="1.0615E-05"
        ixy="1.0566E-21"
        ixz="-4.2285E-11"
        iyy="1.0548E-05"
        iyz="-9.7435E-22"
        izz="2.1103E-05" />
    </inertial>

    <visual>
      <origin
        xyz="0 0 0"
        rpy="0 0 0" />
      <geometry>
        <mesh
          filename="package://vss_simulation/meshes/chapeu_link.STL" />
      </geometry>
      <material
        name="">
        <color
          rgba="0.1098 0.1098 0.1098 1" />
      </material>
    </visual>

    <collision>
      <origin
        xyz="0 0 0"
        rpy="0 0 0" />
      <geometry>
        <mesh
          filename="package://vss_simulation/meshes/chapeu_link.STL" />
      </geometry>
    </collision>

  </link>


  <joint
    name="chapeu_joint"
    type="fixed">
    <origin
      xyz="0 -0.0105 0.0653"
      rpy="0 0 0" />
    <parent
      link="corpo" />
    <child
      link="chapeu_link" />
    <axis
      xyz="0 0 0" />
  </joint>


</robot>