<?xml version="1.0" encoding="utf-8"?>
<!-- This URDF was automatically created by SolidWorks to URDF Exporter! Originally created by Stephen Brawner (brawner@gmail.com) 
     Commit Version: 1.5.1-0-g916b5db  Build Version: 1.5.7152.31018
     For more information, please see http://wiki.ros.org/sw_urdf_exporter -->
<robot
  name="vss_simulation">
  <link
    name="corpo">
    <inertial>
      <origin
        xyz="0.00836350345754076 1.00970659242458E-05 0.0193764900612843"
        rpy="0 0 0" />
      <mass
        value="0.114255136924402" />
      <inertia
        ixx="5.05104803499885E-05"
        ixy="-5.9966389340311E-09"
        ixz="-4.91396335027749E-06"
        iyy="5.6432509407802E-05"
        iyz="4.34697103483597E-13"
        izz="8.10707764885917E-05" />
    </inertial>
    <visual>
      <origin
        xyz="0 0 0"
        rpy="0 0 0" />
      <geometry>
        <mesh
          filename="package://vss_simulation/meshes/corpo.STL" />
      </geometry>
      <material
        name="">
        <color
          rgba="1 1 1 1" />
      </material>
    </visual>
    <collision>
      <origin
        xyz="0 0 0"
        rpy="0 0 0" />
      <geometry>
        <mesh
          filename="package://vss_simulation/meshes/corpo.STL" />
      </geometry>
    </collision>
  </link>
  <link
    name="roda_dir_link">
    <inertial>
      <origin
        xyz="-4.52E-08 -3.5231E-06 -0.0037178"
        rpy="0 0 0" />
      <mass
        value="0.017155" />
      <inertia
        ixx="4.35E-06"
        ixy="1.602E-15"
        ixz="-8.2955E-17"
        iyy="4.3503E-06"
        iyz="6.2765E-17"
        izz="8.5226E-06" />
    </inertial>
    <visual>
      <origin
        xyz="0 0 0"
        rpy="0 0 0" />
      <geometry>
        <mesh
          filename="package://vss_simulation/meshes/roda_dir_link.STL" />
      </geometry>
      <material
        name="">
        <color
          rgba="0.69804 0.69804 0.69804 1" />
      </material>
    </visual>
    <collision>
      <origin
        xyz="0 0 0"
        rpy="0 0 0" />
      <geometry>
        <mesh
          filename="package://vss_simulation/meshes/roda_dir_link.STL" />
      </geometry>
    </collision>
  </link>
  <joint
    name="roda_dir_joint"
    type="continuous">
    <!-- Manually added -->
    <!-- damp = stall_torque/max_vel -->
    <dynamics damping="2.3e-3" friction="0.01" />
    <limit effort="108e-3" velocity="100" />
    <!-- Manually added -->
    <origin
      xyz="0 -0.0362 0.0267989207102477"
      rpy="1.5707963267949 -0.257204591428631 0" />
    <parent
      link="corpo" />
    <child
      link="roda_dir_link" />
    <axis
      xyz="0 0 -1" />
  </joint>
  <link
    name="roda_esq_link">
    <inertial>
      <origin
        xyz="-1.35457345451506E-07 -3.52311700731883E-06 -0.00371783524643296"
        rpy="0 0 0" />
      <mass
        value="0.0171546672764287" />
      <inertia
        ixx="4.35000652569962E-06"
        ixy="-1.60203523539383E-15"
        ixz="-8.29546398889933E-17"
        iyy="4.35027517811247E-06"
        iyz="-6.27621403080168E-17"
        izz="8.52255775209774E-06" />
    </inertial>
    <visual>
      <origin
        xyz="0 0 0"
        rpy="0 0 0" />
      <geometry>
        <mesh
          filename="package://vss_simulation/meshes/roda_esq_link.STL" />
      </geometry>
      <material
        name="">
        <color
          rgba="0.698039215686274 0.698039215686274 0.698039215686274 1" />
      </material>
    </visual>
    <collision>
      <origin
        xyz="0 0 0"
        rpy="0 0 0" />
      <geometry>
        <mesh
          filename="package://vss_simulation/meshes/roda_esq_link.STL" />
      </geometry>
    </collision>
  </link>
  <joint
    name="roda_esq_joint"
    type="continuous">
    <!-- Manually added -->
    <!-- damp = stall_torque/max_vel -->
    <dynamics damping="2.3e-3" friction="0.01" />
    <limit effort="108e-3" velocity="100" />
    <!-- Manually added -->
    <origin
      xyz="0 0.0362 0.02679871482879"
      rpy="1.5707963267949 -0.0133976378081295 3.14159265358979" />
    <parent
      link="corpo" />
    <child
      link="roda_esq_link" />
    <axis
      xyz="0 0 1" />
  </joint>
  <link
    name="chapeu_link">
    <inertial>
      <origin
        xyz="-6.79850457059594E-06 -2.42861286636753E-17 -0.00274999999999997"
        rpy="0 0 0" />
      <mass
        value="0.0141218190526683" />
      <inertia
        ixx="6.55901198190287E-06"
        ixy="1.84011897115871E-21"
        ixz="1.11996728466913E-23"
        iyy="6.49220829461271E-06"
        iyz="5.66918800962593E-22"
        izz="1.30365100483357E-05" />
    </inertial>
    <visual>
      <origin
        xyz="0 0 0"
        rpy="0 0 0" />
      <geometry>
        <mesh
          filename="package://vss_simulation/meshes/chapeu_link.STL" />
      </geometry>
      <material
        name="">
        <color
          rgba="0.109803921568627 0.109803921568627 0.109803921568627 1" />
      </material>
    </visual>
    <collision>
      <origin
        xyz="0 0 0"
        rpy="0 0 0" />
      <geometry>
        <mesh
          filename="package://vss_simulation/meshes/chapeu_link.STL" />
      </geometry>
    </collision>
  </link>
  <joint
    name="chapeu_joint"
    type="fixed">
    <origin
      xyz="0.00525000000000002 0 0.0653"
      rpy="0 0 0" />
    <parent
      link="corpo" />
    <child
      link="chapeu_link" />
    <axis
      xyz="0 0 0" />
  </joint>
  <link
    name="tile_sup_esq_link">
    <inertial>
      <origin
        xyz="0.01875 0.01875 -0.000750000000000015"
        rpy="0 0 0" />
      <mass
        value="0.002109375" />
      <inertia
        ixx="2.47587890625E-07"
        ixy="1.00823390502864E-23"
        ixz="0"
        iyy="2.47587890625E-07"
        iyz="1.03397576569128E-24"
        izz="4.94384765625E-07" />
    </inertial>
    <visual>
      <origin
        xyz="0 0 0"
        rpy="0 0 0" />
      <geometry>
        <mesh
          filename="package://vss_simulation/meshes/tile_sup_esq_link.STL" />
      </geometry>
      <material
        name="">
        <color
          rgba="0.792156862745098 0.819607843137255 0.933333333333333 1" />
      </material>
    </visual>
    <collision>
      <origin
        xyz="0 0 0"
        rpy="0 0 0" />
      <geometry>
        <mesh
          filename="package://vss_simulation/meshes/tile_sup_esq_link.STL" />
      </geometry>
    </collision>
  </link>
  <joint
    name="tile_sup_esq_joint"
    type="fixed">
    <origin
      xyz="0 0 0"
      rpy="0 0 0" />
    <parent
      link="chapeu_link" />
    <child
      link="tile_sup_esq_link" />
    <axis
      xyz="0 0 0" />
  </joint>
  <link
    name="tile_sup_dir_link">
    <inertial>
      <origin
        xyz="0.01875 -0.01875 -0.000750000000000001"
        rpy="0 0 0" />
      <mass
        value="0.002109375" />
      <inertia
        ixx="2.47587890625E-07"
        ixy="3.42363164806114E-39"
        ixz="0"
        iyy="2.47587890625E-07"
        iyz="2.69049305150365E-40"
        izz="4.94384765625E-07" />
    </inertial>
    <visual>
      <origin
        xyz="0 0 0"
        rpy="0 0 0" />
      <geometry>
        <mesh
          filename="package://vss_simulation/meshes/tile_sup_dir_link.STL" />
      </geometry>
      <material
        name="">
        <color
          rgba="0.792156862745098 0.819607843137255 0.933333333333333 1" />
      </material>
    </visual>
    <collision>
      <origin
        xyz="0 0 0"
        rpy="0 0 0" />
      <geometry>
        <mesh
          filename="package://vss_simulation/meshes/tile_sup_dir_link.STL" />
      </geometry>
    </collision>
  </link>
  <joint
    name="tile_sup_dir_joint"
    type="fixed">
    <origin
      xyz="0 0 0"
      rpy="0 0 0" />
    <parent
      link="chapeu_link" />
    <child
      link="tile_sup_dir_link" />
    <axis
      xyz="0 0 0" />
  </joint>
  <link
    name="tile_inf_esq_link">
    <inertial>
      <origin
        xyz="-0.01875 0.01875 -0.000750000000000001"
        rpy="0 0 0" />
      <mass
        value="0.002109375" />
      <inertia
        ixx="2.47587890625E-07"
        ixy="8.27180612553025E-24"
        ixz="-2.69049305150365E-40"
        iyy="2.47587890625E-07"
        iyz="-1.79366203433577E-40"
        izz="4.94384765625E-07" />
    </inertial>
    <visual>
      <origin
        xyz="0 0 0"
        rpy="0 0 0" />
      <geometry>
        <mesh
          filename="package://vss_simulation/meshes/tile_inf_esq_link.STL" />
      </geometry>
      <material
        name="">
        <color
          rgba="0.792156862745098 0.819607843137255 0.933333333333333 1" />
      </material>
    </visual>
    <collision>
      <origin
        xyz="0 0 0"
        rpy="0 0 0" />
      <geometry>
        <mesh
          filename="package://vss_simulation/meshes/tile_inf_esq_link.STL" />
      </geometry>
    </collision>
  </link>
  <joint
    name="tile_inf_esq_joint"
    type="fixed">
    <origin
      xyz="0 0 0"
      rpy="0 0 0" />
    <parent
      link="chapeu_link" />
    <child
      link="tile_inf_esq_link" />
    <axis
      xyz="0 0 0" />
  </joint>
  <link
    name="tile_inf_dir_link">
    <inertial>
      <origin
        xyz="-0.01875 -0.01875 -0.000750000000000001"
        rpy="0 0 0" />
      <mass
        value="0.002109375" />
      <inertia
        ixx="2.47587890625E-07"
        ixy="2.86985925493722E-39"
        ixz="0"
        iyy="2.47587890625E-07"
        iyz="2.69049305150365E-40"
        izz="4.94384765625E-07" />
    </inertial>
    <visual>
      <origin
        xyz="0 0 0"
        rpy="0 0 0" />
      <geometry>
        <mesh
          filename="package://vss_simulation/meshes/tile_inf_dir_link.STL" />
      </geometry>
      <material
        name="">
        <color
          rgba="0.792156862745098 0.819607843137255 0.933333333333333 1" />
      </material>
    </visual>
    <collision>
      <origin
        xyz="0 0 0"
        rpy="0 0 0" />
      <geometry>
        <mesh
          filename="package://vss_simulation/meshes/tile_inf_dir_link.STL" />
      </geometry>
    </collision>
  </link>
  <joint
    name="tile_inf_dir_joint"
    type="fixed">
    <origin
      xyz="0 0 0"
      rpy="0 0 0" />
    <parent
      link="chapeu_link" />
    <child
      link="tile_inf_dir_link" />
    <axis
      xyz="0 0 0" />
  </joint>
</robot>