<sdf version='1.6'>
  <model name='vss_robot'>
    <link name='Corpo'>
      <pose frame=''>0 0 0 0 -0 0</pose>
      <inertial>
        <pose frame=''>0.000774 0 -0.038284 0 -0 0</pose>
        <mass>0.12206</mass>
        <inertia>
          <ixx>5.6918e-05</ixx>
          <ixy>-5.9966e-09</ixy>
          <ixz>-4.914e-06</ixz>
          <iyy>6.5745e-05</iyy>
          <iyz>4.347e-13</iyz>
          <izz>9.8955e-05</izz>
        </inertia>
      </inertial>
      <collision name='Corpo_collision'>
        <pose frame=''>0 0 0 0 -0 0</pose>
        <geometry>
          <mesh>
            <scale>1 1 1</scale>
            <uri>model://vss_robot/meshes/Corpo.STL</uri>
          </mesh>
        </geometry>
      </collision>
      <visual name='Corpo_visual'>
        <pose frame=''>0 0 0 0 -0 0</pose>
        <geometry>
          <mesh>
            <scale>1 1 1</scale>
            <uri>model://vss_robot/meshes/Corpo.STL</uri>
          </mesh>
        </geometry>
      </visual>
    </link>
    <link name='RodaDir'>
      <pose frame=''>-0.005249 -0.0362 -0.038501 1.5708 -0.2572 0</pose>
      <inertial>
        <pose frame=''>-0 -4e-06 -0.003718 0 -0 0</pose>
        <mass>0.0171547</mass>
        <inertia>
          <ixx>4.35001e-06</ixx>
          <ixy>1.60204e-15</ixy>
          <ixz>-8.2955e-17</ixz>
          <iyy>4.35028e-06</iyy>
          <iyz>6.2765e-17</iyz>
          <izz>8.52256e-06</izz>
        </inertia>
      </inertial>
      <collision name='RodaDir_collision'>
        <pose frame=''>0 0 0 0 -0 0</pose>
        <geometry>
          <mesh>
            <scale>1 1 1</scale>
            <uri>model://vss_robot/meshes/RodaDir.STL</uri>
          </mesh>
        </geometry>
      </collision>
      <visual name='RodaDir_visual'>
        <pose frame=''>0 0 0 0 -0 0</pose>
        <geometry>
          <mesh>
            <scale>1 1 1</scale>
            <uri>model://vss_robot/meshes/RodaDir.STL</uri>
          </mesh>
        </geometry>
      </visual>
    </link>
    <joint name='RodaDir' type='revolute'>
      <child>RodaDir</child>
      <parent>Corpo</parent>
      <axis>
        <xyz>-1e-06 1 4e-06</xyz>
        <limit>
          <lower>-1e+16</lower>
          <upper>1e+16</upper>
        </limit>
        <dynamics>
          <spring_reference>0</spring_reference>
          <spring_stiffness>0</spring_stiffness>
        </dynamics>
        <use_parent_model_frame>1</use_parent_model_frame>
      </axis>
    </joint>
    <link name='RodaEsq'>
      <pose frame=''>-0.005252 0.0362 -0.038501 1.5708 1.0338 -3.14159</pose>
      <inertial>
        <pose frame=''>3e-06 -2e-06 -0.003718 0 -0 0</pose>
        <mass>0.017155</mass>
        <inertia>
          <ixx>4.3502e-06</ixx>
          <ixy>-1.1633e-10</ixy>
          <ixz>1.2876e-17</ixz>
          <iyy>4.3501e-06</iyy>
          <iyz>-1.0322e-16</iyz>
          <izz>8.5226e-06</izz>
        </inertia>
      </inertial>
      <collision name='RodaEsq_collision'>
        <pose frame=''>0 0 0 0 -0 0</pose>
        <geometry>
          <mesh>
            <scale>1 1 1</scale>
            <uri>model://vss_robot/meshes/RodaEsq.STL</uri>
          </mesh>
        </geometry>
      </collision>
      <visual name='RodaEsq_visual'>
        <pose frame=''>0 0 0 0 -0 0</pose>
        <geometry>
          <mesh>
            <scale>1 1 1</scale>
            <uri>model://vss_robot/meshes/RodaEsq.STL</uri>
          </mesh>
        </geometry>
      </visual>
    </link>
    <joint name='RodaEsq' type='revolute'>
      <child>RodaEsq</child>
      <parent>Corpo</parent>
      <axis>
        <xyz>-4e-06 1 -2e-06</xyz>
        <limit>
          <lower>-1e+16</lower>
          <upper>1e+16</upper>
        </limit>
        <dynamics>
          <spring_reference>0</spring_reference>
          <spring_stiffness>0</spring_stiffness>
        </dynamics>
        <use_parent_model_frame>1</use_parent_model_frame>
      </axis>
    </joint>
  </model>
</sdf>
<sdf version='1.6'>
  <model name='vss_robot'>
    <link name='Corpo'>
      <pose frame=''>0 0 0 0 -0 0</pose>
      <inertial>
        <pose frame=''>0.000774 0 -0.038284 0 -0 0</pose>
        <mass>0.12206</mass>
        <inertia>
          <ixx>5.6918e-05</ixx>
          <ixy>-5.9966e-09</ixy>
          <ixz>-4.914e-06</ixz>
          <iyy>6.5745e-05</iyy>
          <iyz>4.347e-13</iyz>
          <izz>9.8955e-05</izz>
        </inertia>
      </inertial>
      <collision name='Corpo_collision'>
        <pose frame=''>0 0 0 0 -0 0</pose>
        <geometry>
          <mesh>
            <scale>1 1 1</scale>
            <uri>model://vss_robot/meshes/Corpo.STL</uri>
          </mesh>
        </geometry>
      </collision>
      <visual name='Corpo_visual'>
        <pose frame=''>0 0 0 0 -0 0</pose>
        <geometry>
          <mesh>
            <scale>1 1 1</scale>
            <uri>model://vss_robot/meshes/Corpo.STL</uri>
          </mesh>
        </geometry>
      </visual>
    </link>
    <link name='RodaDir'>
      <pose frame=''>-0.005249 -0.0362 -0.038501 1.5708 -0.2572 0</pose>
      <inertial>
        <pose frame=''>-0 -4e-06 -0.003718 0 -0 0</pose>
        <mass>0.0171547</mass>
        <inertia>
          <ixx>4.35001e-06</ixx>
          <ixy>1.60204e-15</ixy>
          <ixz>-8.2955e-17</ixz>
          <iyy>4.35028e-06</iyy>
          <iyz>6.2765e-17</iyz>
          <izz>8.52256e-06</izz>
        </inertia>
      </inertial>
    </link>
    <joint name='RodaDir' type='revolute'>
      <child>RodaDir</child>
      <parent>Corpo</parent>
      <axis>
        <xyz>-1e-06 1 4e-06</xyz>
        <limit>
          <lower>-1e+16</lower>
          <upper>1e+16</upper>
        </limit>
        <dynamics>
          <spring_reference>0</spring_reference>
          <spring_stiffness>0</spring_stiffness>
        </dynamics>
        <use_parent_model_frame>1</use_parent_model_frame>
      </axis>
    </joint>
    <link name='RodaEsq'>
      <pose frame=''>-0.005252 0.0362 -0.038501 1.5708 1.0338 -3.14159</pose>
      <inertial>
        <pose frame=''>3e-06 -2e-06 -0.003718 0 -0 0</pose>
        <mass>0.017155</mass>
        <inertia>
          <ixx>4.3502e-06</ixx>
          <ixy>-1.1633e-10</ixy>
          <ixz>1.2876e-17</ixz>
          <iyy>4.3501e-06</iyy>
          <iyz>-1.0322e-16</iyz>
          <izz>8.5226e-06</izz>
        </inertia>
      </inertial>
      <collision name='RodaEsq_collision'>
        <pose frame=''>0 0 0 0 -0 0</pose>
        <geometry>
          <mesh>
            <scale>1 1 1</scale>
            <uri>model://vss_robot/meshes/RodaEsq.STL</uri>
          </mesh>
        </geometry>
      </collision>
      <visual name='RodaEsq_visual'>
        <pose frame=''>0 0 0 0 -0 0</pose>
        <geometry>
          <mesh>
            <scale>1 1 1</scale>
            <uri>model://vss_robot/meshes/RodaEsq.STL</uri>
          </mesh>
        </geometry>
      </visual>
    </link>
    <joint name='RodaEsq' type='revolute'>
      <child>RodaEsq</child>
      <parent>Corpo</parent>
      <axis>
        <xyz>-4e-06 1 -2e-06</xyz>
        <limit>
          <lower>-1e+16</lower>
          <upper>1e+16</upper>
        </limit>
        <dynamics>
          <spring_reference>0</spring_reference>
          <spring_stiffness>0</spring_stiffness>
        </dynamics>
        <use_parent_model_frame>1</use_parent_model_frame>
      </axis>
    </joint>
  </model>
</sdf>
